    try {
        someFunction();
    } catch (...) {
        std::cerr << "An unknown exception occurred!\n";
    }
